Workbook

Sheet Assumptions
A1: APPLE INC. — MODEL ASSUMPTIONS
A3: Assumption | B3: FY2026E | C3: FY2027E | D3: FY2028E | E3: Notes
A4: REVENUE GROWTH
A5: Products Revenue Growth % | B5: 0.04 | C5: 0.04 | D5: 0.04 | E5: FY2025 returned to growth. Assume stable growth.
A6: Services Revenue Growth % | B6: 0.12 | C6: 0.11 | D6: 0.1 | E6: Growth slows as business becomes larger
A7: MARGIN ASSUMPTIONS
A8: Gross Margin % | B8: 0.47 | C8: 0.472 | D8: 0.475 | E8: Rising margins - services represent more of TR
A9: R&D as % of Revenue | B9: 0.083 | C9: 0.084 | D9: 0.085 | E9: R&D spending steadily increased
A10: SG&A as % of Revenue | B10: 0.066 | C10: 0.066 | D10: 0.066 | E10: SG&A has been stable
A11: Effective Tax Rate % | B11: 0.16 | C11: 0.16 | D11: 0.16 | E11: Normalized rate (FY2024 high due to tax charge)
A12: BALANCE SHEET DRIVERS
A13: Days Sales Outstanding (DSO) | B13: 35 | C13: 35 | D13: 35 | E13: Accounts Receivable / Revenue × 365
A14: Days Inventory Outstanding | B14: 10 | C14: 10 | D14: 10 | E14: Inventory / Cost of Sales × 365
A15: Days Payable Outstanding | B15: 115 | C15: 115 | D15: 115 | E15: Accounts Payable / Cost of Sales × 365
A16: CapEx as % of Revenue | B16: 0.031 | C16: 0.031 | D16: 0.031 | E16: ABS(CapEx) / Revenue
A17: D&A as % of Revenue | B17: 0.028 | C17: 0.028 | D17: 0.028 | E17: D&A / Revenue
A18: OTHER
A19: Diluted Weighted-Average Shares (mm) | B19: 14630 | C19: 14264 | D19: 13907 | E19: Assuming a rounded 2.5% decline
A20: Annual Dividend per Share ($) | B20: 1.06 | C20: 1.1 | D20: 1.14 | E20: Increase $0.04 every year

Sheet Income Statement
A1: APPLE INC. — INCOME STATEMENT ($mm)
B2: Historical | G2: Projected
A3: Line Item | B3: FY2021 | C3: FY2022 | D3: FY2023 | E3: FY2024 | F3: FY2025 | G3: FY2026E | H3: FY2027E | I3: FY2028E
A4: REVENUE
A5: Products Revenue | B5: 297392 | C5: 316199 | D5: 298085 | E5: 294866 | F5: 307003 | G5: =F5*(1+Assumptions!B5) -> 319283.12 | H5: =G5*(1+Assumptions!C5) -> 332054.44 | I5: =H5*(1+Assumptions!D5) -> 345336.62
A6: Services Revenue | B6: 68425 | C6: 78129 | D6: 85200 | E6: 96169 | F6: 109158 | G6: =F6*(1+Assumptions!B6) -> 122256.96 | H6: =G6*(1+Assumptions!C6) -> 135705.23 | I6: =H6*(1+Assumptions!D6) -> 149275.75
A7: Total Revenue | B7: =B5+B6 -> 365817 | C7: =C5+C6 -> 394328 | D7: =D5+D6 -> 383285 | E7: =E5+E6 -> 391035 | F7: =F5+F6 -> 416161 | G7: =G5+G6 -> 441540.08 | H7: =H5+H6 -> 467759.67 | I7: =I5+I6 -> 494612.37
A9: COSTS & EXPENSES
A10: Cost of Sales | B10: 212981 | C10: 223546 | D10: 214137 | E10: 210352 | F10: 220960 | G10: =G7*(1-Assumptions!B8) -> 234016.24 | H10: =H7*(1-Assumptions!C8) -> 246977.11 | I10: =I7*(1-Assumptions!D8) -> 259671.49
A11: Gross Profit | B11: =B7-B10 -> 152836 | C11: =C7-C10 -> 170782 | D11: =D7-D10 -> 169148 | E11: =E7-E10 -> 180683 | F11: =F7-F10 -> 195201 | G11: =G7-G10 -> 207523.84 | H11: =H7-H10 -> 220782.56 | I11: =I7-I10 -> 234940.88
A12: Gross Margin % | B12: =IFERROR(B11/B7,"-") -> 0.4177936 | C12: =IFERROR(C11/C7,"-") -> 0.43309631 | D12: =IFERROR(D11/D7,"-") -> 0.4413113 | E12: =IFERROR(E11/E7,"-") -> 0.4620635 | F12: =IFERROR(F11/F7,"-") -> 0.46905164 | G12: =IFERROR(G11/G7,"-") -> 0.47 | H12: =IFERROR(H11/H7,"-") -> 0.472 | I12: =IFERROR(I11/I7,"-") -> 0.475
A14: Research & Development | B14: 21914 | C14: 26251 | D14: 29915 | E14: 31370 | F14: 34550 | G14: =G7*Assumptions!B9 -> 36647.827 | H14: =H7*Assumptions!C9 -> 39291.812 | I14: =I7*Assumptions!D9 -> 42042.052
A15: Selling, General & Admin | B15: 21973 | C15: 25094 | D15: 24932 | E15: 26097 | F15: 27601 | G15: =G7*Assumptions!B10 -> 29141.645 | H15: =H7*Assumptions!C10 -> 30872.138 | I15: =I7*Assumptions!D10 -> 32644.416
A16: Total Operating Expenses | B16: =B14+B15 -> 43887 | C16: =C14+C15 -> 51345 | D16: =D14+D15 -> 54847 | E16: =E14+E15 -> 57467 | F16: =F14+F15 -> 62151 | G16: =G14+G15 -> 65789.472 | H16: =H14+H15 -> 70163.951 | I16: =I14+I15 -> 74686.468
A17: Operating Income (EBIT) | B17: =B11-B16 -> 108949 | C17: =C11-C16 -> 119437 | D17: =D11-D16 -> 114301 | E17: =E11-E16 -> 123216 | F17: =F11-F16 -> 133050 | G17: =G11-G16 -> 141734.37 | H17: =H11-H16 -> 150618.61 | I17: =I11-I16 -> 160254.41
A18: EBIT Margin % | B18: =IFERROR(B17/B7,"-") -> 0.29782378 | C18: =IFERROR(C17/C7,"-") -> 0.30288744 | D18: =IFERROR(D17/D7,"-") -> 0.29821412 | E18: =IFERROR(E17/E7,"-") -> 0.31510223 | F18: =IFERROR(F17/F7,"-") -> 0.319708 | G18: =IFERROR(G17/G7,"-") -> 0.321 | H18: =IFERROR(H17/H7,"-") -> 0.322 | I18: =IFERROR(I17/I7,"-") -> 0.324
A20: Interest & Other Income, net | B20: 258 | C20: -334 | D20: -565 | E20: 269 | F20: -321 | G20: =F20 -> -321 | H20: =G20 -> -321 | I20: =H20 -> -321
A21: Pre-Tax Income | B21: =B17+B20 -> 109207 | C21: =C17+C20 -> 119103 | D21: =D17+D20 -> 113736 | E21: =E17+E20 -> 123485 | F21: =F17+F20 -> 132729 | G21: =G17+G20 -> 141413.37 | H21: =H17+H20 -> 150297.61 | I21: =I17+I20 -> 159933.41
A22: Income Tax Expense | B22: 14527 | C22: 19300 | D22: 16741 | E22: 29749 | F22: 20719 | G22: =G21*Assumptions!B11 -> 22626.139 | H22: =H21*Assumptions!C11 -> 24047.618 | I22: =I21*Assumptions!D11 -> 25589.345
A23: Net Income | B23: =B21-B22 -> 94680 | C23: =C21-C22 -> 99803 | D23: =D21-D22 -> 96995 | E23: =E21-E22 -> 93736 | F23: =F21-F22 -> 112010 | G23: =G21-G22 -> 118787.23 | H23: =H21-H22 -> 126250 | I23: =I21-I22 -> 134344.06
A24: Net Margin % | B24: =IFERROR(B23/B7,"-") -> 0.25881793 | C24: =IFERROR(C23/C7,"-") -> 0.25309641 | D24: =IFERROR(D23/D7,"-") -> 0.25306234 | E24: =IFERROR(E23/E7,"-") -> 0.23971256 | F24: =IFERROR(F23/F7,"-") -> 0.26915064 | G24: =IFERROR(G23/G7,"-") -> 0.26902932 | H24: =IFERROR(H23/H7,"-") -> 0.26990355 | I24: =IFERROR(I23/I7,"-") -> 0.27161485
A26: EPS (Diluted, $) | B26: 5.61 | C26: 6.11 | D26: 6.13 | E26: 6.08 | F26: 7.46 | G26: =IFERROR(G23/Assumptions!B19,"-") -> 8.1194277 | H26: =IFERROR(H23/Assumptions!C19,"-") -> 8.8509531 | I26: =IFERROR(I23/Assumptions!D19,"-") -> 9.6601757

Sheet Balance Sheet
A1: APPLE INC. — BALANCE SHEET ($mm)
A2: Line Item | B2: FY2021 | C2: FY2022 | D2: FY2023 | E2: FY2024 | F2: FY2025 | G2: FY2026E | H2: FY2027E | I2: FY2028E
A3: ASSETS
A4: Current Assets
A5: Cash & Cash Equivalents | B5: 34940 | C5: 23646 | D5: 29965 | E5: 29943 | F5: 35934 | G5: ='Cash Flow Statement'!G37 -> 54696.088 | H5: ='Cash Flow Statement'!H37 -> 81258.665 | I5: ='Cash Flow Statement'!I37 -> 115533.8
A6: Marketable Securities | B6: 27699 | C6: 24658 | D6: 31590 | E6: 35228 | F6: 18763 | G6: =F6 -> 18763 | H6: =G6 -> 18763 | I6: =H6 -> 18763
A7: Accounts Receivable, net | B7: 26278 | C7: 28184 | D7: 29508 | E7: 33410 | F7: 39777 | G7: ='Income Statement'!G7*Assumptions!B13/365 -> 42339.46 | H7: ='Income Statement'!H7*Assumptions!C13/365 -> 44853.667 | I7: ='Income Statement'!I7*Assumptions!D13/365 -> 47428.583
A8: Inventories | B8: 6580 | C8: 4946 | D8: 6331 | E8: 7286 | F8: 5718 | G8: ='Income Statement'!G10*Assumptions!B14/365 -> 6411.4039 | H8: ='Income Statement'!H10*Assumptions!C14/365 -> 6766.4961 | I8: ='Income Statement'!I10*Assumptions!D14/365 -> 7114.2875
A9: Vendor Non-Trade Receivables | B9: 25228 | C9: 32748 | D9: 31477 | E9: 32833 | F9: 33180 | G9: =F9 -> 33180 | H9: =G9 -> 33180 | I9: =H9 -> 33180
A10: Other Current Assets | B10: 14111 | C10: 21223 | D10: 14695 | E10: 14287 | F10: 14585 | G10: =F10 -> 14585 | H10: =G10 -> 14585 | I10: =H10 -> 14585
A11: Total Current Assets | B11: =SUM(B5:B10) -> 134836 | C11: =SUM(C5:C10) -> 135405 | D11: =SUM(D5:D10) -> 143566 | E11: =SUM(E5:E10) -> 152987 | F11: =SUM(F5:F10) -> 147957 | G11: =SUM(G5:G10) -> 169974.95 | H11: =SUM(H5:H10) -> 199406.83 | I11: =SUM(I5:I10) -> 236604.68
A13: Non-Current Assets
A14: Marketable Securities | B14: 127877 | C14: 120805 | D14: 100544 | E14: 91479 | F14: 77723 | G14: =F14 -> 77723 | H14: =G14 -> 77723 | I14: =H14 -> 77723
A15: Property, Plant & Equipment, net | B15: 39440 | C15: 42117 | D15: 43715 | E15: 45680 | F15: 49834 | G15: =F15-'Cash Flow Statement'!G20-'Cash Flow Statement'!G5 -> 51158.62 | H15: =G15-'Cash Flow Statement'!H20-'Cash Flow Statement'!H5 -> 52561.899 | I15: =H15-'Cash Flow Statement'!I20-'Cash Flow Statement'!I5 -> 54045.736
A16: Other Non-Current Assets | B16: 48849 | C16: 54428 | D16: 64758 | E16: 74834 | F16: 83727 | G16: =F16 -> 83727 | H16: =G16 -> 83727 | I16: =H16 -> 83727
A17: Total Non-Current Assets | B17: =SUM(B14:B16) -> 216166 | C17: =SUM(C14:C16) -> 217350 | D17: =SUM(D14:D16) -> 209017 | E17: =SUM(E14:E16) -> 211993 | F17: =SUM(F14:F16) -> 211284 | G17: =SUM(G14:G16) -> 212608.62 | H17: =SUM(H14:H16) -> 214011.9 | I17: =SUM(I14:I16) -> 215495.74
A18: TOTAL ASSETS | B18: =B11+B17 -> 351002 | C18: =C11+C17 -> 352755 | D18: =D11+D17 -> 352583 | E18: =E11+E17 -> 364980 | F18: =F11+F17 -> 359241 | G18: =G11+G17 -> 382583.57 | H18: =H11+H17 -> 413418.73 | I18: =I11+I17 -> 452100.41
A20: LIABILITIES & EQUITY
A21: Current Liabilities
A22: Accounts Payable | B22: 54763 | C22: 64115 | D22: 62611 | E22: 68960 | F22: 69860 | G22: ='Income Statement'!G10*Assumptions!B15/365 -> 73731.145 | H22: ='Income Statement'!H10*Assumptions!C15/365 -> 77814.705 | I22: ='Income Statement'!I10*Assumptions!D15/365 -> 81814.307
A23: Other Current Liabilities | B23: 47493 | C23: 60845 | D23: 58829 | E23: 78304 | F23: 66387 | G23: =F23 -> 66387 | H23: =G23 -> 66387 | I23: =H23 -> 66387
A24: Deferred Revenue | B24: 7612 | C24: 7912 | D24: 8061 | E24: 8249 | F24: 9055 | G24: =F24 -> 9055 | H24: =G24 -> 9055 | I24: =H24 -> 9055
A25: Commercial Paper | B25: 6000 | C25: 9982 | D25: 5985 | E25: 9967 | F25: 7979 | G25: =F25 -> 7979 | H25: =G25 -> 7979 | I25: =H25 -> 7979
A26: Term Debt | B26: 9613 | C26: 11128 | D26: 9822 | E26: 10912 | F26: 12350 | G26: =F26 -> 12350 | H26: =G26 -> 12350 | I26: =H26 -> 12350
A27: Total Current Liabilities | B27: =SUM(B22:B26) -> 125481 | C27: =SUM(C22:C26) -> 153982 | D27: =SUM(D22:D26) -> 145308 | E27: =SUM(E22:E26) -> 176392 | F27: =SUM(F22:F26) -> 165631 | G27: =SUM(G22:G26) -> 169502.14 | H27: =SUM(H22:H26) -> 173585.7 | I27: =SUM(I22:I26) -> 177585.31
A29: Non-Current Liabilities
A30: Long-term Debt | B30: 109106 | C30: 98959 | D30: 95281 | E30: 85750 | F30: 78328 | G30: =F30 -> 78328 | H30: =G30 -> 78328 | I30: =H30 -> 78328
A31: Other Non-Current Liabilities | B31: 53325 | C31: 49142 | D31: 49848 | E31: 45888 | F31: 41549 | G31: =F31 -> 41549 | H31: =G31 -> 41549 | I31: =H31 -> 41549
A32: Total Non-Current Liabilities | B32: =SUM(B30:B31) -> 162431 | C32: =SUM(C30:C31) -> 148101 | D32: =SUM(D30:D31) -> 145129 | E32: =SUM(E30:E31) -> 131638 | F32: =SUM(F30:F31) -> 119877 | G32: =SUM(G30:G31) -> 119877 | H32: =SUM(H30:H31) -> 119877 | I32: =SUM(I30:I31) -> 119877
A33: TOTAL LIABILITIES | B33: =B27+B32 -> 287912 | C33: =C27+C32 -> 302083 | D33: =D27+D32 -> 290437 | E33: =E27+E32 -> 308030 | F33: =F27+F32 -> 285508 | G33: =G27+G32 -> 289379.14 | H33: =H27+H32 -> 293462.7 | I33: =I27+I32 -> 297462.31
A35: Shareholders' Equity
A36: Common Stock & APIC | B36: 57365 | C36: 64849 | D36: 73812 | E36: 83276 | F36: 93568 | G36: =F36+'Cash Flow Statement'!G6 -> 106431 | H36: =G36+'Cash Flow Statement'!H6 -> 119294 | I36: =H36+'Cash Flow Statement'!I6 -> 132157
A37: Retained Earnings (Deficit) | B37: 5562 | C37: -3068 | D37: -214 | E37: -19154 | F37: -14264 | G37: =F37+'Income Statement'!G23+'Cash Flow Statement'!G25+'Cash Flow Statement'!G26+'Cash Flow Statement'!G27 -> -7655.5728 | H37: =G37+'Income Statement'!H23+'Cash Flow Statement'!H25+'Cash Flow Statement'!H26+'Cash Flow Statement'!H27 -> 6233.0228 | I37: =H37+'Income Statement'!I23+'Cash Flow Statement'!I25+'Cash Flow Statement'!I26+'Cash Flow Statement'!I27 -> 28052.106
A38: Accumulated OCI | B38: 163 | C38: -11109 | D38: -11452 | E38: -7172 | F38: -5571 | G38: =F38 -> -5571 | H38: =G38 -> -5571 | I38: =H38 -> -5571
A39: Total Shareholders' Equity | B39: =SUM(B36:B38) -> 63090 | C39: =SUM(C36:C38) -> 50672 | D39: =SUM(D36:D38) -> 62146 | E39: =SUM(E36:E38) -> 56950 | F39: =SUM(F36:F38) -> 73733 | G39: =SUM(G36:G38) -> 93204.427 | H39: =SUM(H36:H38) -> 119956.02 | I39: =SUM(I36:I38) -> 154638.11
A40: TOTAL LIABILITIES & EQUITY | B40: =B33+B39 -> 351002 | C40: =C33+C39 -> 352755 | D40: =D33+D39 -> 352583 | E40: =E33+E39 -> 364980 | F40: =F33+F39 -> 359241 | G40: =G33+G39 -> 382583.57 | H40: =H33+H39 -> 413418.73 | I40: =I33+I39 -> 452100.41

Sheet Cash Flow Statement
A1: APPLE INC. — CASH FLOW STATEMENT ($mm)
A2: Line Item | B2: FY2021 | C2: FY2022 | D2: FY2023 | E2: FY2024 | F2: FY2025 | G2: FY2026E | H2: FY2027E | I2: FY2028E
A3: OPERATING ACTIVITIES
A4: Net Income | B4: ='Income Statement'!B23 -> 94680 | C4: ='Income Statement'!C23 -> 99803 | D4: ='Income Statement'!D23 -> 96995 | E4: ='Income Statement'!E23 -> 93736 | F4: ='Income Statement'!F23 -> 112010 | G4: ='Income Statement'!G23 -> 118787.23 | H4: ='Income Statement'!H23 -> 126250 | I4: ='Income Statement'!I23 -> 134344.06
A5: Depreciation & Amortization | B5: 11284 | C5: 11104 | D5: 11519 | E5: 11445 | F5: 11698 | G5: ='Income Statement'!G7*Assumptions!B17 -> 12363.122 | H5: ='Income Statement'!H7*Assumptions!C17 -> 13097.271 | I5: ='Income Statement'!I7*Assumptions!D17 -> 13849.146
A6: Share-Based Compensation | B6: 7906 | C6: 9038 | D6: 10833 | E6: 11688 | F6: 12863 | G6: =F6 -> 12863 | H6: =G6 -> 12863 | I6: =H6 -> 12863
A7: Other | B7: -4921 | C7: 1006 | D7: -2227 | E7: -2266 | F7: -89 | G7: =0 -> 0 | H7: =G7 -> 0 | I7: =H7 -> 0
A8: Change in Accounts Receivable | B8: -10125 | C8: -1823 | D8: -1688 | E8: -3788 | F8: -6682 | G8: ='Balance Sheet'!F7-'Balance Sheet'!G7 -> -2562.4597 | H8: ='Balance Sheet'!G7-'Balance Sheet'!H7 -> -2514.2073 | I8: ='Balance Sheet'!H7-'Balance Sheet'!I7 -> -2574.9165
A9: Change in Inventories | B9: -2642 | C9: 1484 | D9: -1618 | E9: -1046 | F9: 1400 | G9: ='Balance Sheet'!F8-'Balance Sheet'!G8 -> -693.4039 | H9: ='Balance Sheet'!G8-'Balance Sheet'!H8 -> -355.09215 | I9: ='Balance Sheet'!H8-'Balance Sheet'!I8 -> -347.79147
A10: Change in Vendor Recievable | B10: -3903 | C10: -7520 | D10: 1271 | E10: -1356 | F10: -347 | G10: ='Balance Sheet'!F9-'Balance Sheet'!G9 -> 0 | H10: ='Balance Sheet'!G9-'Balance Sheet'!H9 -> 0 | I10: ='Balance Sheet'!H9-'Balance Sheet'!I9 -> 0
A11: Other Current & Non-Current Assets | B11: -8042 | C11: -6499 | D11: -5684 | E11: -11731 | F11: -9197 | G11: =('Balance Sheet'!F10+'Balance Sheet'!F16)-('Balance Sheet'!G10+'Balance Sheet'!G16) -> 0 | H11: =('Balance Sheet'!G10+'Balance Sheet'!G16)-('Balance Sheet'!H10+'Balance Sheet'!H16) -> 0 | I11: =('Balance Sheet'!H10+'Balance Sheet'!H16)-('Balance Sheet'!I10+'Balance Sheet'!I16) -> 0
A12: Change in Accounts Payable | B12: 12326 | C12: 9448 | D12: -1889 | E12: 6020 | F12: 902 | G12: ='Balance Sheet'!G22-'Balance Sheet'!F22 -> 3871.1449 | H12: ='Balance Sheet'!H22-'Balance Sheet'!G22 -> 4083.5598 | I12: ='Balance Sheet'!I22-'Balance Sheet'!H22 -> 3999.6019
A13: Other Current & Non-Current Liabilities | B13: 7475 | C13: 6110 | D13: 3031 | E13: 15552 | F13: -11076 | G13: =('Balance Sheet'!G23+'Balance Sheet'!G24+'Balance Sheet'!G31)-('Balance Sheet'!F23+'Balance Sheet'!F24+'Balance Sheet'!F31) -> 0 | H13: =('Balance Sheet'!H23+'Balance Sheet'!H24+'Balance Sheet'!H31)-('Balance Sheet'!G23+'Balance Sheet'!G24+'Balance Sheet'!G31) -> 0 | I13: =('Balance Sheet'!I23+'Balance Sheet'!I24+'Balance Sheet'!I31)-('Balance Sheet'!H23+'Balance Sheet'!H24+'Balance Sheet'!H31) -> 0
A14: Cash from Operations (CFO) | B14: =SUM(B4:B13) -> 104038 | C14: =SUM(C4:C13) -> 122151 | D14: =SUM(D4:D13) -> 110543 | E14: =SUM(E4:E13) -> 118254 | F14: =SUM(F4:F13) -> 111482 | G14: =SUM(G4:G13) -> 144628.63 | H14: =SUM(H4:H13) -> 153424.53 | I14: =SUM(I4:I13) -> 162133.1
A16: INVESTING ACTIVITIES
A17: Purchases of Marketable Securities | B17: -109558 | C17: -76923 | D17: -29513 | E17: -48656 | F17: -24407 | G17: 0 | H17: 0 | I17: 0
A18: Proceeds from Maturities | B18: 59023 | C18: 29917 | D18: 39686 | E18: 51211 | F18: 40907 | G18: 0 | H18: 0 | I18: 0
A19: Proceeds from Sales | B19: 47460 | C19: 37446 | D19: 5828 | E19: 11135 | F19: 12890 | G19: 0 | H19: 0 | I19: 0
A20: Capital Expenditures (CapEx) | B20: -11085 | C20: -10708 | D20: -10959 | E20: -9447 | F20: -12715 | G20: =-'Income Statement'!G7*Assumptions!B16 -> -13687.742 | H20: =-'Income Statement'!H7*Assumptions!C16 -> -14500.55 | I20: =-'Income Statement'!I7*Assumptions!D16 -> -15332.983
A21: Other | B21: -385 | C21: -2086 | D21: -1337 | E21: -1308 | F21: -1480 | G21: =0 -> 0 | H21: =G21 -> 0 | I21: =H21 -> 0
A22: Cash from Investing (CFI) | B22: =SUM(B17:B21) -> -14545 | C22: =SUM(C17:C21) -> -22354 | D22: =SUM(D17:D21) -> 3705 | E22: =SUM(E17:E21) -> 2935 | F22: =SUM(F17:F21) -> 15195 | G22: =SUM(G17:G21) -> -13687.742 | H22: =SUM(H17:H21) -> -14500.55 | I22: =SUM(I17:I21) -> -15332.983
A24: FINANCING ACTIVITIES
A25: Payment for Taxes - Net Share Equity | B25: -6556 | C25: -6223 | D25: -5431 | E25: -5441 | F25: -5960 | G25: =F25 -> -5960 | H25: =G25 -> -5960 | I25: =H25 -> -5960
A26: Dividends Paid | B26: -14467 | C26: -14841 | D26: -15025 | E26: -15234 | F26: -15421 | G26: =-Assumptions!B19*Assumptions!B20 -> -15507.8 | H26: =-Assumptions!C19*Assumptions!C20 -> -15690.4 | I26: =-Assumptions!D19*Assumptions!D20 -> -15853.98
A27: Repurchases of Common Stock | B27: -85971 | C27: -89402 | D27: -77550 | E27: -94949 | F27: -90711 | G27: =F27 -> -90711 | H27: =G27 -> -90711 | I27: =H27 -> -90711
A28: Proceeds from Debt Issuance | B28: 20393 | C28: 5465 | D28: 5228 | E28: - | F28: 4481 | G28: 0 | H28: =G28 -> 0 | I28: =H28 -> 0
A29: Debt Repayments | B29: -8750 | C29: -9543 | D29: -11151 | E29: -9958 | F29: -10932 | G29: 0 | H29: =G29 -> 0 | I29: =H29 -> 0
A30: Proceeds from/(Repayments of) Commercial Paper, net | B30: 1022 | C30: 3955 | D30: -3978 | E30: 3960 | F30: -2032 | G30: 0 | H30: =G30 -> 0 | I30: =H30 -> 0
A31: Other Financing Activities | B31: 976 | C31: -160 | D31: -581 | E31: -361 | F31: -111 | G31: 0 | H31: =G31 -> 0 | I31: =H31 -> 0
A32: Cash from Financing (CFF) | B32: =SUM(B25:B31) -> -93353 | C32: =SUM(C25:C31) -> -110749 | D32: =SUM(D25:D31) -> -108488 | E32: =SUM(E25:E31) -> -121983 | F32: =SUM(F25:F31) -> -120686 | G32: =SUM(G25:G31) -> -112178.8 | H32: =SUM(H25:H31) -> -112361.4 | I32: =SUM(I25:I31) -> -112524.98
A34: CASH RECONCILIATION
A35: Net Change in Cash | B35: =B14+B22+B32 -> -3860 | C35: =C14+C22+C32 -> -10952 | D35: =D14+D22+D32 -> 5760 | E35: =E14+E22+E32 -> -794 | F35: =F14+F22+F32 -> 5991 | G35: =G14+G22+G32 -> 18762.088 | H35: =H14+H22+H32 -> 26562.577 | I35: =I14+I22+I32 -> 34275.14
A36: Beginning Cash | B36: 39789 | C36: 35929 | D36: 24977 | E36: 30737 | F36: 29943 | G36: =F37 -> 35934 | H36: =G37 -> 54696.088 | I36: =H37 -> 81258.665
A37: Ending Cash | B37: =B35+B36 -> 35929 | C37: =C35+C36 -> 24977 | D37: =D35+D36 -> 30737 | E37: =E35+E36 -> 29943 | F37: =F35+F36 -> 35934 | G37: =G35+G36 -> 54696.088 | H37: =H35+H36 -> 81258.665 | I37: =I35+I36 -> 115533.8
A38: Less: Restricted Cash | B38: 989 | C38: 1331 | D38: 772 | E38: 0 | F38: 0

Sheet DCF Valuation
A1: APPLE INC. — DCF VALUATION ($mm)
A2: WACC INPUTS
A3: Risk-Free Rate (10-yr Treasury) | B3: 0.0462 | G3: ~4.5% as of 2024
A4: Equity Risk Premium | B4: 0.0418 | G4: ~5.5% (Damodaran)
A5: Beta (AAPL) | B5: 1.2 | G5: ~1.25 (Yahoo Finance)
A6: Cost of Equity [=Rf + β × ERP] | B6: =B3+B5*B4 -> 0.09636 | G6: Formula
A7: Pre-tax Cost of Debt | B7: 0.04 | G7: From 10-K Notes
A8: Tax Rate | B8: =Assumptions!B11 -> 0.16 | G8: Link to Assumptions sheet
A9: After-tax Cost of Debt | B9: =B7*(1-B8) -> 0.0336 | G9: Formula
A10: Weight of Equity (E/V) | B10: 0.9791 | G10: Market cap / (Market cap + Debt)
A11: Weight of Debt (D/V) | B11: =1-B10 -> 0.0209 | G11: 1 - Weight of Equity
A12: WACC | B12: =B6*B10+B9*B11 -> 0.095048316 | G12: WACC formula: Ke x We + Kd x Wd
A14: FREE CASH FLOW TO FIRM (FCFF)
A15: Line Item | B15: FY2026E | C15: FY2027E | D15: FY2028E
A16: EBIT | B16: ='Income Statement'!G17 -> 141734.37 | C16: ='Income Statement'!H17 -> 150618.61 | D16: ='Income Statement'!I17 -> 160254.41
A17: Tax on EBIT [= EBIT × Tax Rate] | B17: =-B16*$B$8 -> -22677.499 | C17: =-C16*$B$8 -> -24098.978 | D17: =-D16*$B$8 -> -25640.705
A18: NOPAT [= EBIT × (1 - Tax Rate)] | B18: =B16+B17 -> 119056.87 | C18: =C16+C17 -> 126519.64 | D18: =D16+D17 -> 134613.7
A19: + D&A | B19: ='Cash Flow Statement'!G5 -> 12363.122 | C19: ='Cash Flow Statement'!H5 -> 13097.271 | D19: ='Cash Flow Statement'!I5 -> 13849.146
A20: - CapEx | B20: ='Cash Flow Statement'!G20 -> -13687.742 | C20: ='Cash Flow Statement'!H20 -> -14500.55 | D20: ='Cash Flow Statement'!I20 -> -15332.983
A21: ± Changes in Working Capital | B21: =SUM('Cash Flow Statement'!G8:G13) -> 615.28124 | C21: =SUM('Cash Flow Statement'!H8:H13) -> 1214.2603 | D21: =SUM('Cash Flow Statement'!I8:I13) -> 1076.894
A22: Free Cash Flow to Firm (FCFF) | B22: =SUM(B18:B21) -> 118347.53 | C22: =SUM(C18:C21) -> 126330.62 | D22: =SUM(D18:D21) -> 134206.76
A24: TERMINAL VALUE & VALUATION
A25: Terminal Growth Rate (g) | B25: 0.025 | G25: ~2.5–3.0% (nominal GDP)
A26: Terminal Value [= FCFFn × (1+g) / (WACC-g)] | B26: =D22*(1+B25)/($B$12-B25) -> 1963814.9 | G26: Gordon Growth Model
A27: PV of Terminal Value | B27: =B26/(1+$B$12)^3 -> 1495549.2 | G27: Discount back at WACC
A28: PV of Projected FCFFs | B28: =B22/(1+$B$12)+C22/(1+$B$12)^2+D22/(1+$B$12)^3 -> 315632.55 | G28: Sum of discounted FCFFs
A29: Enterprise Value (EV) | B29: =B27+B28 -> 1811181.8 | G29: PV of FCFFs + PV of Terminal Value
A30: + Cash & Marketable Securities | B30: ='Balance Sheet'!F5+'Balance Sheet'!F6+'Balance Sheet'!F14 -> 132420 | G30: From Balance Sheet
A31: - Total Debt | B31: ='Balance Sheet'!F25+'Balance Sheet'!F26+'Balance Sheet'!F30 -> 98657 | G31: From Balance Sheet
A32: Equity Value | B32: =B29+B30-B31 -> 1844944.8 | G32: EV + Cash - Debt
A33: Shares Outstanding (mm) | B33: =Assumptions!B19 -> 14630 | G33: From Assumptions sheet
A34: Implied Share Price ($) | B34: =B32/B33 -> 126.10696 | G34: Equity Value divided by Shares
A35: Current Market Price ($) | B35: 313.36 | G35: Yahoo Finance
A36: Upside / Downside (%) | B36: =(B34-B35)/B35 -> -0.59756524 | G36: (Implied Price - Market Price) / Market Price
A38: SENSITIVITY TABLE — Implied Share Price ($)
A39: Rows = Terminal Growth Rate | Columns = WACC
A40: g \ WACC | B40: 8.0% | C40: 9.0% | D40: 10.0% | E40: 11.0% | F40: 12.0%
A41: 2.0% | B41: =(($B$22/(1+B$40)+$C$22/(1+B$40)^2+$D$22/(1+B$40)^3)+($D$22*(1+$A41)/(B$40-$A41))/(1+B$40)^3+$B$30-$B$31)/$B$33 -> 148.27956 | C41: =(($B$22/(1+C$40)+$C$22/(1+C$40)^2+$D$22/(1+C$40)^3)+($D$22*(1+$A41)/(C$40-$A41))/(1+C$40)^3+$B$30-$B$31)/$B$33 -> 127.29807 | D41: =(($B$22/(1+D$40)+$C$22/(1+D$40)^2+$D$22/(1+D$40)^3)+($D$22*(1+$A41)/(D$40-$A41))/(1+D$40)^3+$B$30-$B$31)/$B$33 -> 111.56463 | E41: =(($B$22/(1+E$40)+$C$22/(1+E$40)^2+$D$22/(1+E$40)^3)+($D$22*(1+$A41)/(E$40-$A41))/(1+E$40)^3+$B$30-$B$31)/$B$33 -> 99.329825 | F41: =(($B$22/(1+F$40)+$C$22/(1+F$40)^2+$D$22/(1+F$40)^3)+($D$22*(1+$A41)/(F$40-$A41))/(1+F$40)^3+$B$30-$B$31)/$B$33 -> 89.543985
A42: 2.5% | B42: =(($B$22/(1+B$40)+$C$22/(1+B$40)^2+$D$22/(1+B$40)^3)+($D$22*(1+$A42)/(B$40-$A42))/(1+B$40)^3+$B$30-$B$31)/$B$33 -> 160.19578 | C42: =(($B$22/(1+C$40)+$C$22/(1+C$40)^2+$D$22/(1+C$40)^3)+($D$22*(1+$A42)/(C$40-$A42))/(1+C$40)^3+$B$30-$B$31)/$B$33 -> 135.78275 | D42: =(($B$22/(1+D$40)+$C$22/(1+D$40)^2+$D$22/(1+D$40)^3)+($D$22*(1+$A42)/(D$40-$A42))/(1+D$40)^3+$B$30-$B$31)/$B$33 -> 117.8824 | E42: =(($B$22/(1+E$40)+$C$22/(1+E$40)^2+$D$22/(1+E$40)^3)+($D$22*(1+$A42)/(E$40-$A42))/(1+E$40)^3+$B$30-$B$31)/$B$33 -> 104.19606 | F42: =(($B$22/(1+F$40)+$C$22/(1+F$40)^2+$D$22/(1+F$40)^3)+($D$22*(1+$A42)/(F$40-$A42))/(1+F$40)^3+$B$30-$B$31)/$B$33 -> 93.392919
A43: 3.0% | B43: =(($B$22/(1+B$40)+$C$22/(1+B$40)^2+$D$22/(1+B$40)^3)+($D$22*(1+$A43)/(B$40-$A43))/(1+B$40)^3+$B$30-$B$31)/$B$33 -> 174.49525 | C43: =(($B$22/(1+C$40)+$C$22/(1+C$40)^2+$D$22/(1+C$40)^3)+($D$22*(1+$A43)/(C$40-$A43))/(1+C$40)^3+$B$30-$B$31)/$B$33 -> 145.68155 | D43: =(($B$22/(1+D$40)+$C$22/(1+D$40)^2+$D$22/(1+D$40)^3)+($D$22*(1+$A43)/(D$40-$A43))/(1+D$40)^3+$B$30-$B$31)/$B$33 -> 125.1027 | E43: =(($B$22/(1+E$40)+$C$22/(1+E$40)^2+$D$22/(1+E$40)^3)+($D$22*(1+$A43)/(E$40-$A43))/(1+E$40)^3+$B$30-$B$31)/$B$33 -> 109.67057 | F43: =(($B$22/(1+F$40)+$C$22/(1+F$40)^2+$D$22/(1+F$40)^3)+($D$22*(1+$A43)/(F$40-$A43))/(1+F$40)^3+$B$30-$B$31)/$B$33 -> 97.669512
...

Sheet Dashboard
A1: APPLE INC. — EXECUTIVE DASHBOARD
B2: Historical | G2: Projected
A3: KEY METRICS SUMMARY
A4: Metric | B4: FY2021 | C4: FY2022 | D4: FY2023 | E4: FY2024 | F4: FY2025 | G4: FY2026E | H4: FY2027E | I4: FY2028E
A5: Revenue ($mm) | B5: ='Income Statement'!B7 -> 365817 | C5: ='Income Statement'!C7 -> 394328 | D5: ='Income Statement'!D7 -> 383285 | E5: ='Income Statement'!E7 -> 391035 | F5: ='Income Statement'!F7 -> 416161 | G5: ='Income Statement'!G7 -> 441540.08 | H5: ='Income Statement'!H7 -> 467759.67 | I5: ='Income Statement'!I7 -> 494612.37
A6: Net Income ($mm) | B6: ='Income Statement'!B23 -> 94680 | C6: ='Income Statement'!C23 -> 99803 | D6: ='Income Statement'!D23 -> 96995 | E6: ='Income Statement'!E23 -> 93736 | F6: ='Income Statement'!F23 -> 112010 | G6: ='Income Statement'!G23 -> 118787.23 | H6: ='Income Statement'!H23 -> 126250 | I6: ='Income Statement'!I23 -> 134344.06
A7: Gross Margin % | B7: ='Income Statement'!B12 -> 0.4177936 | C7: ='Income Statement'!C12 -> 0.43309631 | D7: ='Income Statement'!D12 -> 0.4413113 | E7: ='Income Statement'!E12 -> 0.4620635 | F7: ='Income Statement'!F12 -> 0.46905164 | G7: ='Income Statement'!G12 -> 0.47 | H7: ='Income Statement'!H12 -> 0.472 | I7: ='Income Statement'!I12 -> 0.475
A8: EBIT Margin % | B8: ='Income Statement'!B18 -> 0.29782378 | C8: ='Income Statement'!C18 -> 0.30288744 | D8: ='Income Statement'!D18 -> 0.29821412 | E8: ='Income Statement'!E18 -> 0.31510223 | F8: ='Income Statement'!F18 -> 0.319708 | G8: ='Income Statement'!G18 -> 0.321 | H8: ='Income Statement'!H18 -> 0.322 | I8: ='Income Statement'!I18 -> 0.324
A9: Net Margin % | B9: ='Income Statement'!B24 -> 0.25881793 | C9: ='Income Statement'!C24 -> 0.25309641 | D9: ='Income Statement'!D24 -> 0.25306234 | E9: ='Income Statement'!E24 -> 0.23971256 | F9: ='Income Statement'!F24 -> 0.26915064 | G9: ='Income Statement'!G24 -> 0.26902932 | H9: ='Income Statement'!H24 -> 0.26990355 | I9: ='Income Statement'!I24 -> 0.27161485
A10: EPS (Diluted) | B10: ='Income Statement'!B26 -> 5.61 | C10: ='Income Statement'!C26 -> 6.11 | D10: ='Income Statement'!D26 -> 6.13 | E10: ='Income Statement'!E26 -> 6.08 | F10: ='Income Statement'!F26 -> 7.46 | G10: ='Income Statement'!G26 -> 8.1194277 | H10: ='Income Statement'!H26 -> 8.8509531 | I10: ='Income Statement'!I26 -> 9.6601757
A11: FCF ($mm) | B11: ='Cash Flow Statement'!B14+'Cash Flow Statement'!B20 -> 92953 | C11: ='Cash Flow Statement'!C14+'Cash Flow Statement'!C20 -> 111443 | D11: ='Cash Flow Statement'!D14+'Cash Flow Statement'!D20 -> 99584 | E11: ='Cash Flow Statement'!E14+'Cash Flow Statement'!E20 -> 108807 | F11: ='Cash Flow Statement'!F14+'Cash Flow Statement'!F20 -> 98767 | G11: ='Cash Flow Statement'!G14+'Cash Flow Statement'!G20 -> 130940.89 | H11: ='Cash Flow Statement'!H14+'Cash Flow Statement'!H20 -> 138923.98 | I11: ='Cash Flow Statement'!I14+'Cash Flow Statement'!I20 -> 146800.12
A12: Shares Out. (mm) | B12: 16864.919 | C12: 16325.819 | D12: 15812.547 | E12: 15408.095 | F12: 15004.697 | G12: =Assumptions!B19 -> 14630 | H12: =Assumptions!C19 -> 14264 | I12: =Assumptions!D19 -> 13907
